<?xml version="1.0" encoding="UTF-8" standalone="no"?>
<?pydev-testrun version="1.0"?><pydev-testsuite>
<summary errors="1" failures="0" finished="true" name="Test Run: 0" tests="0" total_time="Finished in: 0.00 secs."/>
<test location="C:\Users\Cara\Documents\COMPSCI\2_Software Engineering\SEWorkspace\PySysInfo\setup.py" status="error" test="setup" time="0">
<stdout/>
<stderr><![CDATA[Traceback (most recent call last):
  File "C:\Users\Cara\.p2\pool\plugins\org.python.pydev_5.5.0.201701191708\pysrc\_pydev_runfiles\pydev_runfiles.py", line 468, in __get_module_from_str
    mod = __import__(modname)
  File "C:\Users\Cara\.p2\pool\plugins\org.python.pydev_5.5.0.201701191708\pysrc\setup.py", line 68, in <module>
    data_files.append(('pydevd_attach_to_process', [os.path.join('pydevd_attach_to_process', f) for f in os.listdir('pydevd_attach_to_process') if accept_file(f)]))
FileNotFoundError: [WinError 3] The system cannot find the path specified: 'pydevd_attach_to_process'
ERROR: Module: setup could not be imported (file: C:\Users\Cara\Documents\COMPSCI\2_Software Engineering\SEWorkspace\PySysInfo\setup.py).
]]></stderr>
</test>
<launch mode="run">
<launch_memento><![CDATA[<?xml version="1.0" encoding="UTF-8" standalone="no"?>
<launchConfiguration local="true" path="PySysInfo setup.py (1)"/>
]]></launch_memento>
</launch>
</pydev-testsuite>
